Workbook
Name UPDATE: 'Data Sheet'!$E$1

Sheet Profit & Loss
A1: ='Data Sheet'!B1 -> HCL TECHNOLOGIES LTD | H1: =UPDATE
A3: Narration | B3: ='Data Sheet'!B16 -> 42825 | C3: ='Data Sheet'!C16 -> 43190 | D3: ='Data Sheet'!D16 -> 43555 | E3: ='Data Sheet'!E16 -> 43921 | F3: ='Data Sheet'!F16 -> 44286 | G3: ='Data Sheet'!G16 -> 44651 | H3: ='Data Sheet'!H16 -> 45016 | I3: ='Data Sheet'!I16 -> 45382 | ... K3: ='Data Sheet'!K16 -> 46112 | L3: Trailing | M3: Best Case | N3: Worst Case
A4: Sales | B4: ='Data Sheet'!B17 -> 47568 | C4: ='Data Sheet'!C17 -> 50569 | D4: ='Data Sheet'!D17 -> 60427 | E4: ='Data Sheet'!E17 -> 70676 | F4: ='Data Sheet'!F17 -> 75379 | G4: ='Data Sheet'!G17 -> 85651 | H4: ='Data Sheet'!H17 -> 101456 | I4: ='Data Sheet'!I17 -> 109913 | ... K4: ='Data Sheet'!K17 -> 130144 | L4: =SUM(Quarters!H4:K4) -> 134374 | M4: =$K4+M23*K4 -> 144696.6 | N4: =$K4+N23*L4 -> 141773.76
A5: Expenses | B5: =SUM('Data Sheet'!B18,'Data Sheet'!B20:B24, -1*'Data Sheet'!B19) -> 37178 | C5: =SUM('Data Sheet'!C18,'Data Sheet'!C20:C24, -1*'Data Sheet'!C19) -> 39323 | D5: =SUM('Data Sheet'!D18,'Data Sheet'!D20:D24, -1*'Data Sheet'!D19) -> 46501 | E5: =SUM('Data Sheet'!E18,'Data Sheet'!E20:E24, -1*'Data Sheet'!E19) -> 53360 | F5: =SUM('Data Sheet'!F18,'Data Sheet'!F20:F24, -1*'Data Sheet'!F19) -> 55331 | G5: =SUM('Data Sheet'!G18,'Data Sheet'!G20:G24, -1*'Data Sheet'!G19) -> 65122 | H5: =SUM('Data Sheet'!H18,'Data Sheet'!H20:H24, -1*'Data Sheet'!H19) -> 78828 | I5: =SUM('Data Sheet'!I18,'Data Sheet'!I20:I24, -1*'Data Sheet'!I19) -> 85715 | ... K5: =SUM('Data Sheet'!K18,'Data Sheet'!K20:K24, -1*'Data Sheet'!K19) -> 103392 | L5: =SUM(Quarters!H5:K5) -> 106835 | M5: =M4-M6 -> 113718.55 | N5: =N4-N6 -> 112718.23
A6: Operating Profit | B6: =B4-B5 -> 10390 | C6: =C4-C5 -> 11246 | D6: =D4-D5 -> 13926 | E6: =E4-E5 -> 17316 | F6: =F4-F5 -> 20048 | G6: =G4-G5 -> 20529 | H6: =H4-H5 -> 22628 | I6: =I4-I5 -> 24198 | ... K6: =K4-K5 -> 26752 | L6: =SUM(Quarters!H6:K6) -> 27539 | M6: =M4*M24 -> 30978.052 | N6: =N4*N24 -> 29055.529
A7: Other Income | B7: ='Data Sheet'!B25 -> 1069 | C7: ='Data Sheet'!C25 -> 1230 | D7: ='Data Sheet'!D25 -> 943 | E7: ='Data Sheet'!E25 -> 589 | F7: ='Data Sheet'!F25 -> 927 | G7: ='Data Sheet'!G25 -> 1067 | H7: ='Data Sheet'!H25 -> 1358 | I7: ='Data Sheet'!I25 -> 1495 | ... K7: ='Data Sheet'!K25 -> 574 | L7: =SUM(Quarters!H7:K7) -> 527 | M7: 0 | N7: 0
A8: Depreciation | B8: ='Data Sheet'!B26 -> 828 | C8: ='Data Sheet'!C26 -> 1383 | D8: ='Data Sheet'!D26 -> 2073 | E8: ='Data Sheet'!E26 -> 3420 | F8: ='Data Sheet'!F26 -> 4611 | G8: ='Data Sheet'!G26 -> 4326 | H8: ='Data Sheet'!H26 -> 4145 | I8: ='Data Sheet'!I26 -> 4173 | ... K8: ='Data Sheet'!K26 -> 4355 | L8: =SUM(Quarters!H8:K8) -> 4301 | M8: =+$L8 -> 4301 | N8: =+$L8 -> 4301
A9: Interest | B9: ='Data Sheet'!B27 -> 89 | C9: ='Data Sheet'!C27 -> 69 | D9: ='Data Sheet'!D27 -> 174 | E9: ='Data Sheet'!E27 -> 505 | F9: ='Data Sheet'!F27 -> 511 | G9: ='Data Sheet'!G27 -> 319 | H9: ='Data Sheet'!H27 -> 353 | I9: ='Data Sheet'!I27 -> 553 | ... K9: ='Data Sheet'!K27 -> 869 | L9: =SUM(Quarters!H9:K9) -> 744 | M9: =+$L9 -> 744 | N9: =+$L9 -> 744
A10: Profit before tax | B10: ='Data Sheet'!B28 -> 10542 | C10: ='Data Sheet'!C28 -> 11024 | D10: ='Data Sheet'!D28 -> 12622 | E10: ='Data Sheet'!E28 -> 13980 | F10: ='Data Sheet'!F28 -> 15853 | G10: ='Data Sheet'!G28 -> 16951 | H10: ='Data Sheet'!H28 -> 19488 | I10: ='Data Sheet'!I28 -> 20967 | ... K10: ='Data Sheet'!K28 -> 22102 | L10: =SUM(Quarters!H10:K10) -> 23021 | M10: =M6+M7-SUM(M8:M9) -> 25933.052 | N10: =N6+N7-SUM(N8:N9) -> 24010.529
A11: Tax | B11: ='Data Sheet'!B29 -> 1936 | C11: ='Data Sheet'!C29 -> 2302 | D11: ='Data Sheet'!D29 -> 2502 | E11: ='Data Sheet'!E29 -> 2923 | F11: ='Data Sheet'!F29 -> 4684 | G11: ='Data Sheet'!G29 -> 3428 | H11: ='Data Sheet'!H29 -> 4643 | I11: ='Data Sheet'!I29 -> 5257 | ... K11: ='Data Sheet'!K29 -> 5450 | L11: =SUM(Quarters!H11:K11) -> 5587 | M11: =IF($L10>0,$L11/$L10,0) -> 0.24269146 | N11: =IF($L10>0,$L11/$L10,0) -> 0.24269146
A12: Net profit | B12: ='Data Sheet'!B30 -> 8606 | C12: ='Data Sheet'!C30 -> 8721 | D12: ='Data Sheet'!D30 -> 10120 | E12: ='Data Sheet'!E30 -> 11057 | F12: ='Data Sheet'!F30 -> 11145 | G12: ='Data Sheet'!G30 -> 13499 | H12: ='Data Sheet'!H30 -> 14851 | I12: ='Data Sheet'!I30 -> 15702 | ... K12: ='Data Sheet'!K30 -> 16642 | L12: =SUM(Quarters!H12:K12) -> 17423 | M12: =M10-M11*M10 -> 19639.322 | N12: =N10-N11*N10 -> 18183.379
A13: EPS | B13: =IF('Data Sheet'!B93>0,B12/'Data Sheet'!B93,0) -> 30.158396 | C13: =IF('Data Sheet'!C93>0,C12/'Data Sheet'!C93,0) -> 31.319806 | D13: =IF('Data Sheet'!D93>0,D12/'Data Sheet'!D93,0) -> 37.30738 | E13: =IF('Data Sheet'!E93>0,E12/'Data Sheet'!E93,0) -> 40.745108 | F13: =IF('Data Sheet'!F93>0,F12/'Data Sheet'!F93,0) -> 41.069389 | G13: =IF('Data Sheet'!G93>0,G12/'Data Sheet'!G93,0) -> 49.743892 | H13: =IF('Data Sheet'!H93>0,H12/'Data Sheet'!H93,0) -> 54.72602 | I13: =IF('Data Sheet'!I93>0,I12/'Data Sheet'!I93,0) -> 57.86196 | ... K13: =IF('Data Sheet'!K93>0,K12/'Data Sheet'!K93,0) -> 61.325865 | L13: =IF('Data Sheet'!$B6>0,'Profit & Loss'!L12/'Data Sheet'!$B6,0) -> 64.396825 | M13: =IF('Data Sheet'!$B6>0,'Profit & Loss'!M12/'Data Sheet'!$B6,0) -> 72.58853 | N13: =IF('Data Sheet'!$B6>0,'Profit & Loss'!N12/'Data Sheet'!$B6,0) -> 67.207247
A14: Price to earning | B14: =IF(B15>0,B15/B13,"") -> 14.50276 | C14: =IF(C15>0,C15/C13,"") -> 15.463059 | D14: =IF(D15>0,D15/D13,"") -> 14.574328 | E14: =IF(E15>0,E15/E13,"") -> 10.710488 | F14: =IF(F15>0,F15/F13,"") -> 23.92658 | G14: =IF(G15>0,G15/G13,"") -> 23.394832 | H14: =IF(H15>0,H15/H13,"") -> 19.830603 | I14: =IF(I15>0,I15/I13,"") -> 26.676421 | ... K14: =IF(K15>0,K15/K13,"") -> 21.876577 | L14: =IF(L13>0,L15/L13,0) -> 21.119054 | M14: =M25 -> 23.630732 | N14: =N25 -> 19.720507
A15: Price | B15: ='Data Sheet'!B90 -> 437.38 | C15: ='Data Sheet'!C90 -> 484.3 | D15: ='Data Sheet'!D90 -> 543.73 | E15: ='Data Sheet'!E90 -> 436.4 | F15: ='Data Sheet'!F90 -> 982.65 | G15: ='Data Sheet'!G90 -> 1163.75 | H15: ='Data Sheet'!H90 -> 1085.25 | I15: ='Data Sheet'!I90 -> 1543.55 | ... K15: ='Data Sheet'!K90 -> 1341.6 | L15: ='Data Sheet'!B8 -> 1360 | M15: =M13*M14 -> 1715.3201 | N15: =N13*N14 -> 1325.361
A17: RATIOS:
A18: Dividend Payout | B18: =IF('Data Sheet'!B30>0, 'Data Sheet'!B31/'Data Sheet'!B30, 0) -> 0.39739716 | C18: =IF('Data Sheet'!C30>0, 'Data Sheet'!C31/'Data Sheet'!C30, 0) -> 0.19126247 | D18: =IF('Data Sheet'!D30>0, 'Data Sheet'!D31/'Data Sheet'!D30, 0) -> 0.10711462 | E18: =IF('Data Sheet'!E30>0, 'Data Sheet'!E31/'Data Sheet'!E30, 0) -> 0.24554581 | F18: =IF('Data Sheet'!F30>0, 'Data Sheet'!F31/'Data Sheet'!F30, 0) -> 0.243607 | G18: =IF('Data Sheet'!G30>0, 'Data Sheet'!G31/'Data Sheet'!G30, 0) -> 0.84472924 | H18: =IF('Data Sheet'!H30>0, 'Data Sheet'!H31/'Data Sheet'!H30, 0) -> 0.87751667 | I18: =IF('Data Sheet'!I30>0, 'Data Sheet'!I31/'Data Sheet'!I30, 0) -> 0.89912113 | ... K18: =IF('Data Sheet'!K30>0, 'Data Sheet'!K31/'Data Sheet'!K30, 0) -> 0.88096383
A19: OPM | B19: =IF(B6>0,B6/B4,0) -> 0.21842415 | C19: =IF(C6>0,C6/C4,0) -> 0.22238921 | D19: =IF(D6>0,D6/D4,0) -> 0.23045989 | E19: =IF(E6>0,E6/E4,0) -> 0.24500538 | F19: =IF(F6>0,F6/F4,0) -> 0.26596267 | G19: =IF(G6>0,G6/G4,0) -> 0.23968197 | H19: =IF(H6>0,H6/H4,0) -> 0.22303264 | I19: =IF(I6>0,I6/I4,0) -> 0.22015594 | ... L19: =IF(L6>0,L6/L4,0) -> 0.20494292
G22: TRENDS: | H22: 10 YEARS | I22: 7 YEARS | J22: 5 YEARS | K22: 3 YEARS | L22: RECENT | M22: BEST | N22: WORST
G23: Sales Growth | H23: =IF(B4=0,"",POWER($K4/B4,1/9)-1) -> 0.11832413 | I23: =IF(D4=0,"",POWER($K4/D4,1/7)-1) -> 0.11583253 | J23: =IF(F4=0,"",POWER($K4/F4,1/5)-1) -> 0.11541057 | K23: =IF(H4=0,"",POWER($K4/H4, 1/3)-1) -> 0.08654772 | L23: =IF(ISERROR(MAX(IF(J4=0,"",(K4-J4)/J4),IF(K4=0,"",(L4-K4)/K4))),"",MAX(IF(J4=0,"",(K4-J4)/J4),IF(K4=0,"",(L4-K4)/K4))) -> 0.11181923 | M23: =MAX(K23:L23) -> 0.11181923 | N23: =MIN(H23:L23) -> 0.08654772
G24: OPM | H24: =IF(SUM(B4:$K$4)=0,"",SUMPRODUCT(B19:$K$19,B4:$K$4)/SUM(B4:$K$4)) -> 0.2268242 | I24: =IF(SUM(E4:$K$4)=0,"",SUMPRODUCT(E19:$K$19,E4:$K$4)/SUM(E4:$K$4)) -> 0.2274097 | J24: =IF(SUM(G4:$K$4)=0,"",SUMPRODUCT(G19:$K$19,G4:$K$4)/SUM(G4:$K$4)) -> 0.21978468 | K24: =IF(SUM(I4:$K$4)=0, "", SUMPRODUCT(I19:$K$19,I4:$K$4)/SUM(I4:$K$4)) -> 0.2140897 | L24: =L19 -> 0.20494292 | M24: =MAX(K24:L24) -> 0.2140897 | N24: =MIN(H24:L24) -> 0.20494292
G25: Price to Earning | H25: =IF(ISERROR(AVERAGEIF(B14:$L14,">0")),"",AVERAGEIF(B14:$L14,">0")) -> 19.720507 | I25: =IF(ISERROR(AVERAGEIF(E14:$L14,">0")),"",AVERAGEIF(E14:$L14,">0")) -> 21.548179 | J25: =IF(ISERROR(AVERAGEIF(G14:$L14,">0")),"",AVERAGEIF(G14:$L14,">0")) -> 22.95806 | K25: =IF(ISERROR(AVERAGEIF(I14:$L14,">0")),"",AVERAGEIF(I14:$L14,">0")) -> 23.630732 | L25: =L14 -> 21.119054 | M25: =MAX(K25:L25) -> 23.630732 | N25: =MIN(H25:L25) -> 19.720507

Sheet Quarters
A1: ='Profit & Loss'!A1 -> HCL TECHNOLOGIES LTD | E1: =UPDATE | J1: SCREENER.IN
A3: Narration | B3: ='Data Sheet'!B41 -> 45382 | C3: ='Data Sheet'!C41 -> 45473 | D3: ='Data Sheet'!D41 -> 45565 | E3: ='Data Sheet'!E41 -> 45657 | F3: ='Data Sheet'!F41 -> 45747 | G3: ='Data Sheet'!G41 -> 45838 | H3: ='Data Sheet'!H41 -> 45930 | I3: ='Data Sheet'!I41 -> 46022 | ... K3: ='Data Sheet'!K41 -> 46203
A4: Sales | B4: ='Data Sheet'!B42 -> 28499 | C4: ='Data Sheet'!C42 -> 28057 | D4: ='Data Sheet'!D42 -> 28862 | E4: ='Data Sheet'!E42 -> 29890 | F4: ='Data Sheet'!F42 -> 30246 | G4: ='Data Sheet'!G42 -> 30349 | H4: ='Data Sheet'!H42 -> 31942 | I4: ='Data Sheet'!I42 -> 33872 | ... K4: ='Data Sheet'!K42 -> 34579
A5: Expenses | B5: ='Data Sheet'!B43 -> 22382 | C5: ='Data Sheet'!C43 -> 22264 | D5: ='Data Sheet'!D43 -> 22493 | E5: ='Data Sheet'!E43 -> 23030 | F5: ='Data Sheet'!F43 -> 23764 | G5: ='Data Sheet'!G43 -> 24314 | H5: ='Data Sheet'!H43 -> 25397 | I5: ='Data Sheet'!I43 -> 26460 | ... K5: ='Data Sheet'!K43 -> 27709
A6: Operating Profit | B6: ='Data Sheet'!B50 -> 6117 | C6: ='Data Sheet'!C50 -> 5793 | D6: ='Data Sheet'!D50 -> 6369 | E6: ='Data Sheet'!E50 -> 6860 | F6: ='Data Sheet'!F50 -> 6482 | G6: ='Data Sheet'!G50 -> 6035 | H6: ='Data Sheet'!H50 -> 6545 | I6: ='Data Sheet'!I50 -> 7412 | ... K6: ='Data Sheet'!K50 -> 6870
A7: Other Income | B7: ='Data Sheet'!B44 -> 416 | C7: ='Data Sheet'!C44 -> 1103 | D7: ='Data Sheet'!D44 -> 456 | E7: ='Data Sheet'!E44 -> 477 | F7: ='Data Sheet'!F44 -> 449 | G7: ='Data Sheet'!G44 -> 456 | H7: ='Data Sheet'!H44 -> 415 | I7: ='Data Sheet'!I44 -> -571 | ... K7: ='Data Sheet'!K44 -> 361
A8: Depreciation | B8: ='Data Sheet'!B45 -> 1093 | C8: ='Data Sheet'!C45 -> 998 | D8: ='Data Sheet'!D45 -> 1007 | E8: ='Data Sheet'!E45 -> 1039 | F8: ='Data Sheet'!F45 -> 1040 | G8: ='Data Sheet'!G45 -> 1093 | H8: ='Data Sheet'!H45 -> 1043 | I8: ='Data Sheet'!I45 -> 1127 | ... K8: ='Data Sheet'!K45 -> 1039
A9: Interest | B9: ='Data Sheet'!B46 -> 171 | C9: ='Data Sheet'!C46 -> 191 | D9: ='Data Sheet'!D46 -> 131 | E9: ='Data Sheet'!E46 -> 166 | F9: ='Data Sheet'!F46 -> 156 | G9: ='Data Sheet'!G46 -> 209 | H9: ='Data Sheet'!H46 -> 215 | I9: ='Data Sheet'!I46 -> 205 | ... K9: ='Data Sheet'!K46 -> 84
A10: Profit before tax | B10: ='Data Sheet'!B47 -> 5269 | C10: ='Data Sheet'!C47 -> 5707 | D10: ='Data Sheet'!D47 -> 5687 | E10: ='Data Sheet'!E47 -> 6132 | F10: ='Data Sheet'!F47 -> 5735 | G10: ='Data Sheet'!G47 -> 5189 | H10: ='Data Sheet'!H47 -> 5702 | I10: ='Data Sheet'!I47 -> 5509 | ... K10: ='Data Sheet'!K47 -> 6108
A11: Tax | B11: ='Data Sheet'!B48 -> 1274 | C11: ='Data Sheet'!C48 -> 1448 | D11: ='Data Sheet'!D48 -> 1450 | E11: ='Data Sheet'!E48 -> 1538 | F11: ='Data Sheet'!F48 -> 1426 | G11: ='Data Sheet'!G48 -> 1345 | H11: ='Data Sheet'!H48 -> 1466 | I11: ='Data Sheet'!I48 -> 1427 | ... K11: ='Data Sheet'!K48 -> 1482
A12: Net profit | B12: ='Data Sheet'!B49 -> 3986 | C12: ='Data Sheet'!C49 -> 4257 | D12: ='Data Sheet'!D49 -> 4235 | E12: ='Data Sheet'!E49 -> 4591 | F12: ='Data Sheet'!F49 -> 4307 | G12: ='Data Sheet'!G49 -> 3843 | H12: ='Data Sheet'!H49 -> 4235 | I12: ='Data Sheet'!I49 -> 4076 | ... K12: ='Data Sheet'!K49 -> 4624
A14: OPM | B14: =IF(B4>0,B6/B4,"") -> 0.21463911 | C14: =IF(C4>0,C6/C4,"") -> 0.20647254 | D14: =IF(D4>0,D6/D4,"") -> 0.22067078 | E14: =IF(E4>0,E6/E4,"") -> 0.2295082 | F14: =IF(F4>0,F6/F4,"") -> 0.21430933 | G14: =IF(G4>0,G6/G4,"") -> 0.19885334 | H14: =IF(H4>0,H6/H4,"") -> 0.20490264 | I14: =IF(I4>0,I6/I4,"") -> 0.21882381 | ... K14: =IF(K4>0,K6/K4,"") -> 0.1986755

Sheet Balance Sheet
A1: ='Profit & Loss'!A1 -> HCL TECHNOLOGIES LTD | E1: =UPDATE | J1: SCREENER.IN
A3: Narration | B3: ='Data Sheet'!B56 -> 42825 | C3: ='Data Sheet'!C56 -> 43190 | D3: ='Data Sheet'!D56 -> 43555 | E3: ='Data Sheet'!E56 -> 43921 | F3: ='Data Sheet'!F56 -> 44286 | G3: ='Data Sheet'!G56 -> 44651 | H3: ='Data Sheet'!H56 -> 45016 | I3: ='Data Sheet'!I56 -> 45382 | ... K3: ='Data Sheet'!K56 -> 46112
A4: Equity Share Capital | B4: ='Data Sheet'!B57 -> 285 | C4: ='Data Sheet'!C57 -> 278 | D4: ='Data Sheet'!D57 -> 271 | E4: ='Data Sheet'!E57 -> 543 | F4: ='Data Sheet'!F57 -> 543 | G4: ='Data Sheet'!G57 -> 543 | H4: ='Data Sheet'!H57 -> 543 | I4: ='Data Sheet'!I57 -> 543 | ... K4: ='Data Sheet'!K57 -> 543
A5: Reserves | B5: ='Data Sheet'!B58 -> 32664 | C5: ='Data Sheet'!C58 -> 36108 | D5: ='Data Sheet'!D58 -> 41095 | E5: ='Data Sheet'!E58 -> 50724 | F5: ='Data Sheet'!F58 -> 59370 | G5: ='Data Sheet'!G58 -> 61371 | H5: ='Data Sheet'!H58 -> 64862 | I5: ='Data Sheet'!I58 -> 67720 | ... K5: ='Data Sheet'!K58 -> 74622
A6: Borrowings | B6: ='Data Sheet'!B59 -> 582 | C6: ='Data Sheet'!C59 -> 557 | D6: ='Data Sheet'!D59 -> 4195 | E6: ='Data Sheet'!E59 -> 7986 | F6: ='Data Sheet'!F59 -> 6864 | G6: ='Data Sheet'!G59 -> 6343 | H6: ='Data Sheet'!H59 -> 4794 | I6: ='Data Sheet'!I59 -> 5756 | ... K6: ='Data Sheet'!K59 -> 5215
A7: Other Liabilities | B7: ='Data Sheet'!B60 -> 12231 | C7: ='Data Sheet'!C60 -> 11046 | D7: ='Data Sheet'!D60 -> 12788 | E7: ='Data Sheet'!E60 -> 23566 | F7: ='Data Sheet'!F60 -> 19270 | G7: ='Data Sheet'!G60 -> 20664 | H7: ='Data Sheet'!H60 -> 23051 | I7: ='Data Sheet'!I60 -> 24987 | ... K7: ='Data Sheet'!K60 -> 34732
A8: Total | B8: ='Data Sheet'!B61 -> 45762 | C8: ='Data Sheet'!C61 -> 47989 | D8: ='Data Sheet'!D61 -> 58349 | E8: ='Data Sheet'!E61 -> 82819 | F8: ='Data Sheet'!F61 -> 86047 | G8: ='Data Sheet'!G61 -> 88921 | H8: ='Data Sheet'!H61 -> 93250 | I8: ='Data Sheet'!I61 -> 99006 | ... K8: ='Data Sheet'!K61 -> 115112
A10: Net Block | B10: ='Data Sheet'!B62 -> 15235 | C10: ='Data Sheet'!C62 -> 18753 | D10: ='Data Sheet'!D62 -> 22888 | E10: ='Data Sheet'!E62 -> 37490 | F10: ='Data Sheet'!F62 -> 37145 | G10: ='Data Sheet'!G62 -> 35077 | H10: ='Data Sheet'!H62 -> 34619 | I10: ='Data Sheet'!I62 -> 35063 | ... K10: ='Data Sheet'!K62 -> 37297
A11: Capital Work in Progress | B11: ='Data Sheet'!B63 -> 448 | C11: ='Data Sheet'!C63 -> 320 | D11: ='Data Sheet'!D63 -> 235 | E11: ='Data Sheet'!E63 -> 400 | F11: ='Data Sheet'!F63 -> 312 | G11: ='Data Sheet'!G63 -> 129 | H11: ='Data Sheet'!H63 -> 40 | I11: ='Data Sheet'!I63 -> 108 | ... K11: ='Data Sheet'!K63 -> 142
A12: Investments | B12: ='Data Sheet'!B64 -> 1306 | C12: ='Data Sheet'!C64 -> 2660 | D12: ='Data Sheet'!D64 -> 2305 | E12: ='Data Sheet'!E64 -> 7066 | F12: ='Data Sheet'!F64 -> 6862 | G12: ='Data Sheet'!G64 -> 6351 | H12: ='Data Sheet'!H64 -> 5495 | I12: ='Data Sheet'!I64 -> 7137 | ... K12: ='Data Sheet'!K64 -> 7090
A13: Other Assets | B13: ='Data Sheet'!B65 -> 28773 | C13: ='Data Sheet'!C65 -> 26256 | D13: ='Data Sheet'!D65 -> 32921 | E13: ='Data Sheet'!E65 -> 37863 | F13: ='Data Sheet'!F65 -> 41728 | G13: ='Data Sheet'!G65 -> 47364 | H13: ='Data Sheet'!H65 -> 53096 | I13: ='Data Sheet'!I65 -> 56698 | ... K13: ='Data Sheet'!K65 -> 70583
A14: Total | B14: ='Data Sheet'!B66 -> 45762 | C14: ='Data Sheet'!C66 -> 47989 | D14: ='Data Sheet'!D66 -> 58349 | E14: ='Data Sheet'!E66 -> 82819 | F14: ='Data Sheet'!F66 -> 86047 | G14: ='Data Sheet'!G66 -> 88921 | H14: ='Data Sheet'!H66 -> 93250 | I14: ='Data Sheet'!I66 -> 99006 | ... K14: ='Data Sheet'!K66 -> 115112
A16: Working Capital | B16: =B13-B7 -> 16542 | C16: =C13-C7 -> 15210 | D16: =D13-D7 -> 20133 | E16: =E13-E7 -> 14297 | F16: =F13-F7 -> 22458 | G16: =G13-G7 -> 26700 | H16: =H13-H7 -> 30045 | I16: =I13-I7 -> 31711 | ... K16: =K13-K7 -> 35851
A17: Debtors | B17: ='Data Sheet'!B67 -> 8301 | C17: ='Data Sheet'!C67 -> 9639 | D17: ='Data Sheet'!D67 -> 11706 | E17: ='Data Sheet'!E67 -> 14131 | F17: ='Data Sheet'!F67 -> 17525 | G17: ='Data Sheet'!G67 -> 20671 | H17: ='Data Sheet'!H67 -> 25506 | I17: ='Data Sheet'!I67 -> 25521 | ... K17: ='Data Sheet'!K67 -> 31541
A18: Inventory | B18: ='Data Sheet'!B68 -> 276 | C18: ='Data Sheet'!C68 -> 172 | D18: ='Data Sheet'!D68 -> 91 | E18: ='Data Sheet'!E68 -> 91 | F18: ='Data Sheet'!F68 -> 94 | G18: ='Data Sheet'!G68 -> 161 | H18: ='Data Sheet'!H68 -> 228 | I18: ='Data Sheet'!I68 -> 185 | ... K18: ='Data Sheet'!K68 -> 239
A20: Debtor Days | B20: =IF('Profit & Loss'!B4>0,'Balance Sheet'!B17/('Profit & Loss'!B4/365),0) -> 63.695447 | C20: =IF('Profit & Loss'!C4>0,'Balance Sheet'!C17/('Profit & Loss'!C4/365),0) -> 69.57296 | D20: =IF('Profit & Loss'!D4>0,'Balance Sheet'!D17/('Profit & Loss'!D4/365),0) -> 70.708293 | E20: =IF('Profit & Loss'!E4>0,'Balance Sheet'!E17/('Profit & Loss'!E4/365),0) -> 72.978309 | F20: =IF('Profit & Loss'!F4>0,'Balance Sheet'!F17/('Profit & Loss'!F4/365),0) -> 84.85951 | G20: =IF('Profit & Loss'!G4>0,'Balance Sheet'!G17/('Profit & Loss'!G4/365),0) -> 88.089047 | H20: =IF('Profit & Loss'!H4>0,'Balance Sheet'!H17/('Profit & Loss'!H4/365),0) -> 91.760862 | I20: =IF('Profit & Loss'!I4>0,'Balance Sheet'!I17/('Profit & Loss'!I4/365),0) -> 84.750348 | ... K20: =IF('Profit & Loss'!K4>0,'Balance Sheet'!K17/('Profit & Loss'!K4/365),0) -> 88.459437
A21: Inventory Turnover | B21: =IF('Balance Sheet'!B18>0,'Profit & Loss'!B4/'Balance Sheet'!B18,0) -> 172.34783 | C21: =IF('Balance Sheet'!C18>0,'Profit & Loss'!C4/'Balance Sheet'!C18,0) -> 294.00581 | D21: =IF('Balance Sheet'!D18>0,'Profit & Loss'!D4/'Balance Sheet'!D18,0) -> 664.03297 | E21: =IF('Balance Sheet'!E18>0,'Profit & Loss'!E4/'Balance Sheet'!E18,0) -> 776.65934 | F21: =IF('Balance Sheet'!F18>0,'Profit & Loss'!F4/'Balance Sheet'!F18,0) -> 801.90426 | G21: =IF('Balance Sheet'!G18>0,'Profit & Loss'!G4/'Balance Sheet'!G18,0) -> 531.99379 | H21: =IF('Balance Sheet'!H18>0,'Profit & Loss'!H4/'Balance Sheet'!H18,0) -> 444.98246 | I21: =IF('Balance Sheet'!I18>0,'Profit & Loss'!I4/'Balance Sheet'!I18,0) -> 594.12432 | ... K21: =IF('Balance Sheet'!K18>0,'Profit & Loss'!K4/'Balance Sheet'!K18,0) -> 544.53556
A23: Return on Equity | B23: =IF(SUM('Balance Sheet'!B4:B5)>0,'Profit & Loss'!B12/SUM('Balance Sheet'!B4:B5),"") -> 0.26119154 | C23: =IF(SUM('Balance Sheet'!C4:C5)>0,'Profit & Loss'!C12/SUM('Balance Sheet'!C4:C5),"") -> 0.2396801 | D23: =IF(SUM('Balance Sheet'!D4:D5)>0,'Profit & Loss'!D12/SUM('Balance Sheet'!D4:D5),"") -> 0.24464536 | E23: =IF(SUM('Balance Sheet'!E4:E5)>0,'Profit & Loss'!E12/SUM('Balance Sheet'!E4:E5),"") -> 0.2156748 | F23: =IF(SUM('Balance Sheet'!F4:F5)>0,'Profit & Loss'!F12/SUM('Balance Sheet'!F4:F5),"") -> 0.18601973 | G23: =IF(SUM('Balance Sheet'!G4:G5)>0,'Profit & Loss'!G12/SUM('Balance Sheet'!G4:G5),"") -> 0.21802823 | H23: =IF(SUM('Balance Sheet'!H4:H5)>0,'Profit & Loss'!H12/SUM('Balance Sheet'!H4:H5),"") -> 0.22706215 | I23: =IF(SUM('Balance Sheet'!I4:I5)>0,'Profit & Loss'!I12/SUM('Balance Sheet'!I4:I5),"") -> 0.23002212 | ... K23: =IF(SUM('Balance Sheet'!K4:K5)>0,'Profit & Loss'!K12/SUM('Balance Sheet'!K4:K5),"") -> 0.22140624
A24: Return on Capital Emp | C24: =IF((B4+B5+B6+C4+C5+C6)>0,('Profit & Loss'!C10+'Profit & Loss'!C9)*2/(B4+B5+B6+C4+C5+C6),"") -> 0.31481114 | D24: =IF((C4+C5+C6+D4+D5+D6)>0,('Profit & Loss'!D10+'Profit & Loss'!D9)*2/(C4+C5+C6+D4+D5+D6),"") -> 0.31019102 | E24: =IF((D4+D5+D6+E4+E5+E6)>0,('Profit & Loss'!E10+'Profit & Loss'!E9)*2/(D4+D5+D6+E4+E5+E6),"") -> 0.27639437 | F24: =IF((E4+E5+E6+F4+F5+F6)>0,('Profit & Loss'!F10+'Profit & Loss'!F9)*2/(E4+E5+E6+F4+F5+F6),"") -> 0.2596842 | G24: =IF((F4+F5+F6+G4+G5+G6)>0,('Profit & Loss'!G10+'Profit & Loss'!G9)*2/(F4+F5+F6+G4+G5+G6),"") -> 0.25578743 | H24: =IF((G4+G5+G6+H4+H5+H6)>0,('Profit & Loss'!H10+'Profit & Loss'!H9)*2/(G4+G5+G6+H4+H5+H6),"") -> 0.28660369 | I24: =IF((H4+H5+H6+I4+I5+I6)>0,('Profit & Loss'!I10+'Profit & Loss'!I9)*2/(H4+H5+H6+I4+I5+I6),"") -> 0.29843709 | J24: =IF((I4+I5+I6+J4+J5+J6)>0,('Profit & Loss'!J10+'Profit & Loss'!J9)*2/(I4+I5+I6+J4+J5+J6),"") -> 0.31883961 | K24: =IF((J4+J5+J6+K4+K5+K6)>0,('Profit & Loss'!K10+'Profit & Loss'!K9)*2/(J4+J5+J6+K4+K5+K6),"") -> 0.29391406

Sheet Cash Flow
A1: ='Balance Sheet'!A1 -> HCL TECHNOLOGIES LTD | E1: =UPDATE | J1: SCREENER.IN
A3: Narration | B3: ='Data Sheet'!B81 -> 42825 | C3: ='Data Sheet'!C81 -> 43190 | D3: ='Data Sheet'!D81 -> 43555 | E3: ='Data Sheet'!E81 -> 43921 | F3: ='Data Sheet'!F81 -> 44286 | G3: ='Data Sheet'!G81 -> 44651 | H3: ='Data Sheet'!H81 -> 45016 | I3: ='Data Sheet'!I81 -> 45382 | ... K3: ='Data Sheet'!K81 -> 46112
A4: Cash from Operating Activity | B4: ='Data Sheet'!B82 -> 8995 | C4: ='Data Sheet'!C82 -> 8328 | D4: ='Data Sheet'!D82 -> 8971 | E4: ='Data Sheet'!E82 -> 13359 | F4: ='Data Sheet'!F82 -> 19618 | G4: ='Data Sheet'!G82 -> 16900 | H4: ='Data Sheet'!H82 -> 18009 | I4: ='Data Sheet'!I82 -> 22448 | ... K4: ='Data Sheet'!K82 -> 19975
A5: Cash from Investing Activity | B5: ='Data Sheet'!B83 -> -3890 | C5: ='Data Sheet'!C83 -> -2236 | D5: ='Data Sheet'!D83 -> -3256 | E5: ='Data Sheet'!E83 -> -12332 | F5: ='Data Sheet'!F83 -> -5665 | G5: ='Data Sheet'!G83 -> 1597 | H5: ='Data Sheet'!H83 -> -3573 | I5: ='Data Sheet'!I83 -> -6608 | ... K5: ='Data Sheet'!K83 -> -656
A6: Cash from Financing Activity | B6: ='Data Sheet'!B84 -> -4517 | C6: ='Data Sheet'!C84 -> -5714 | D6: ='Data Sheet'!D84 -> -1471 | E6: ='Data Sheet'!E84 -> -3168 | F6: ='Data Sheet'!F84 -> -11192 | G6: ='Data Sheet'!G84 -> -14508 | H6: ='Data Sheet'!H84 -> -15881 | I6: ='Data Sheet'!I84 -> -15464 | ... K6: ='Data Sheet'!K84 -> -19369
A7: Net Cash Flow | B7: ='Data Sheet'!B85 -> 588 | C7: ='Data Sheet'!C85 -> 378 | D7: ='Data Sheet'!D85 -> 4244 | E7: ='Data Sheet'!E85 -> -2141 | F7: ='Data Sheet'!F85 -> 2761 | G7: ='Data Sheet'!G85 -> 3989 | H7: ='Data Sheet'!H85 -> -1445 | I7: ='Data Sheet'!I85 -> 376 | ... K7: ='Data Sheet'!K85 -> -50

Sheet Data Sheet
A1: COMPANY NAME | B1: HCL TECHNOLOGIES LTD | E1: =IF(B2<>B3, "A NEW VERSION OF THE WORKSHEET IS AVAILABLE", "")
A2: LATEST VERSION | B2: 2.1 | E2: PLEASE DO NOT MAKE ANY CHANGES TO THIS SHEET
A3: CURRENT VERSION | B3: 2.1
A5: META
A6: Number of shares | B6: =IF(B9>0, B9/B8, 0) -> 270.55682
A7: Face Value | B7: 2
A8: Current Price | B8: 1360
A9: Market Capitalization | B9: 367957.27
A15: PROFIT & LOSS
A16: Report Date | B16: 42825 | C16: 43190 | D16: 43555 | E16: 43921 | F16: 44286 | G16: 44651 | H16: 45016 | I16: 45382 | J16: 45747 | K16: 46112
A17: Sales | B17: 47568 | C17: 50569 | D17: 60427 | E17: 70676 | F17: 75379 | G17: 85651 | H17: 101456 | I17: 109913 | J17: 117055 | K17: 130144
A18: Raw Material Cost | B18: 826 | C18: 1251 | D18: 1615 | E18: 1536 | F18: 1698 | G18: 1473 | H18: 2072 | I18: 1754 | J18: 1976 | K18: 2715
A19: Change in Inventory | B19: 11 | C19: -104 | D19: -81 | F19: 3 | G19: 67 | H19: 67 | I19: -43 | J19: -52 | K19: 106
A20: Power and Fuel | B20: 307 | C20: 313 | D20: 336 | E20: 307 | F20: 275 | G20: 291 | H20: 328 | I20: 360 | J20: 355 | K20: 355
A21: Other Mfr. Exp | B21: 9286 | C21: 9388 | D21: 10862 | E21: 12324 | F21: 12084 | G21: 14574 | H21: 17303 | I21: 15651 | J21: 16276 | K21: 19741
A22: Employee Cost | B22: 22866 | C22: 24729 | D22: 29283 | E22: 34928 | F22: 38853 | G22: 46130 | H22: 55280 | I22: 62480 | J22: 66755 | K22: 74143
A23: Selling and admin | B23: 2988 | C23: 2810 | D23: 3519 | E23: 3050 | F23: 1681 | G23: 1866 | H23: 2687 | I23: 3858 | J23: 4504 | K23: 4779
A24: Other Expenses | B24: 916 | C24: 728 | D24: 805 | E24: 1215 | F24: 743 | G24: 855 | H24: 1225 | I24: 1569 | J24: 1633 | K24: 1765
A25: Other Income | B25: 1069 | C25: 1230 | D25: 943 | E25: 589 | F25: 927 | G25: 1067 | H25: 1358 | I25: 1495 | J25: 2485 | K25: 574
A26: Depreciation | B26: 828 | C26: 1383 | D26: 2073 | E26: 3420 | F26: 4611 | G26: 4326 | H26: 4145 | I26: 4173 | J26: 4084 | K26: 4355
A27: Interest | B27: 89 | C27: 69 | D27: 174 | E27: 505 | F27: 511 | G27: 319 | H27: 353 | I27: 553 | J27: 644 | K27: 869
A28: Profit before tax | B28: 10542 | C28: 11024 | D28: 12622 | E28: 13980 | F28: 15853 | G28: 16951 | H28: 19488 | I28: 20967 | J28: 23261 | K28: 22102
A29: Tax | B29: 1936 | C29: 2302 | D29: 2502 | E29: 2923 | F29: 4684 | G29: 3428 | H29: 4643 | I29: 5257 | J29: 5862 | K29: 5450
A30: Net profit | B30: 8606 | C30: 8721 | D30: 10120 | E30: 11057 | F30: 11145 | G30: 13499 | H30: 14851 | I30: 15702 | J30: 17390 | K30: 16642
A31: Dividend Amount | B31: 3420 | C31: 1668 | D31: 1084 | E31: 2715 | F31: 2715 | G31: 11403 | H31: 13032 | I31: 14118 | J31: 16290 | K31: 14661
A40: Quarters
A41: Report Date | B41: 45382 | C41: 45473 | D41: 45565 | E41: 45657 | F41: 45747 | G41: 45838 | H41: 45930 | I41: 46022 | J41: 46112 | K41: 46203
A42: Sales | B42: 28499 | C42: 28057 | D42: 28862 | E42: 29890 | F42: 30246 | G42: 30349 | H42: 31942 | I42: 33872 | J42: 33981 | K42: 34579
A43: Expenses | B43: 22382 | C43: 22264 | D43: 22493 | E43: 23030 | F43: 23764 | G43: 24314 | H43: 25397 | I43: 26460 | J43: 27269 | K43: 27709
A44: Other Income | B44: 416 | C44: 1103 | D44: 456 | E44: 477 | F44: 449 | G44: 456 | H44: 415 | I44: -571 | J44: 322 | K44: 361
A45: Depreciation | B45: 1093 | C45: 998 | D45: 1007 | E45: 1039 | F45: 1040 | G45: 1093 | H45: 1043 | I45: 1127 | J45: 1092 | K45: 1039
A46: Interest | B46: 171 | C46: 191 | D46: 131 | E46: 166 | F46: 156 | G46: 209 | H46: 215 | I46: 205 | J46: 240 | K46: 84
A47: Profit before tax | B47: 5269 | C47: 5707 | D47: 5687 | E47: 6132 | F47: 5735 | G47: 5189 | H47: 5702 | I47: 5509 | J47: 5702 | K47: 6108
A48: Tax | B48: 1274 | C48: 1448 | D48: 1450 | E48: 1538 | F48: 1426 | G48: 1345 | H48: 1466 | I48: 1427 | J48: 1212 | K48: 1482
A49: Net profit | B49: 3986 | C49: 4257 | D49: 4235 | E49: 4591 | F49: 4307 | G49: 3843 | H49: 4235 | I49: 4076 | J49: 4488 | K49: 4624
A50: Operating Profit | B50: 6117 | C50: 5793 | D50: 6369 | E50: 6860 | F50: 6482 | G50: 6035 | H50: 6545 | I50: 7412 | J50: 6712 | K50: 6870
A55: BALANCE SHEET
A56: Report Date | B56: 42825 | C56: 43190 | D56: 43555 | E56: 43921 | F56: 44286 | G56: 44651 | H56: 45016 | I56: 45382 | J56: 45747 | K56: 46112
A57: Equity Share Capital | B57: 285 | C57: 278 | D57: 271 | E57: 543 | F57: 543 | G57: 543 | H57: 543 | I57: 543 | J57: 543 | K57: 543
A58: Reserves | B58: 32664 | C58: 36108 | D58: 41095 | E58: 50724 | F58: 59370 | G58: 61371 | H58: 64862 | I58: 67720 | J58: 69112 | K58: 74622
...
